Workbook
Name UPDATE: 'Data Sheet'!$E$1

Sheet Profit & Loss
A1: ='Data Sheet'!B1 -> TITAN COMPANY LTD | H1: =UPDATE | M1: SCREENER.IN
A3: Narration | B3: ='Data Sheet'!B16 -> 42825 | C3: ='Data Sheet'!C16 -> 43190 | D3: ='Data Sheet'!D16 -> 43555 | E3: ='Data Sheet'!E16 -> 43921 | F3: ='Data Sheet'!F16 -> 44286 | G3: ='Data Sheet'!G16 -> 44651 | H3: ='Data Sheet'!H16 -> 45016 | I3: ='Data Sheet'!I16 -> 45382 | ... K3: ='Data Sheet'!K16 -> 46112 | L3: Trailing | M3: Best Case | N3: Worst Case
A4: Sales | B4: ='Data Sheet'!B17 -> 13260.83 | C4: ='Data Sheet'!C17 -> 16119.77 | D4: ='Data Sheet'!D17 -> 19778.52 | E4: ='Data Sheet'!E17 -> 21052 | F4: ='Data Sheet'!F17 -> 21644 | G4: ='Data Sheet'!G17 -> 28799 | H4: ='Data Sheet'!H17 -> 40575 | I4: ='Data Sheet'!I17 -> 51084 | ... K4: ='Data Sheet'!K17 -> 87584 | L4: =SUM(Quarters!H4:K4) -> 87584 | M4: =$K4+M23*K4 -> 126884.96 | N4: =$K4+N23*L4 -> 108023.86
A5: Expenses | B5: =SUM('Data Sheet'!B18,'Data Sheet'!B20:B24, -1*'Data Sheet'!B19) -> 12096.93 | C5: =SUM('Data Sheet'!C18,'Data Sheet'!C20:C24, -1*'Data Sheet'!C19) -> 14475.57 | D5: =SUM('Data Sheet'!D18,'Data Sheet'!D20:D24, -1*'Data Sheet'!D19) -> 17784.73 | E5: =SUM('Data Sheet'!E18,'Data Sheet'!E20:E24, -1*'Data Sheet'!E19) -> 18589 | F5: =SUM('Data Sheet'!F18,'Data Sheet'!F20:F24, -1*'Data Sheet'!F19) -> 19919 | G5: =SUM('Data Sheet'!G18,'Data Sheet'!G20:G24, -1*'Data Sheet'!G19) -> 25455 | H5: =SUM('Data Sheet'!H18,'Data Sheet'!H20:H24, -1*'Data Sheet'!H19) -> 35693 | I5: =SUM('Data Sheet'!I18,'Data Sheet'!I20:I24, -1*'Data Sheet'!I19) -> 45792 | ... K5: =SUM('Data Sheet'!K18,'Data Sheet'!K20:K24, -1*'Data Sheet'!K19) -> 79229 | L5: =SUM(Quarters!H5:K5) -> 79228 | M5: =M4-M6 -> 114560.57 | N5: =N4-N6 -> 97717.779
A6: Operating Profit | B6: =B4-B5 -> 1163.9 | C6: =C4-C5 -> 1644.2 | D6: =D4-D5 -> 1993.79 | E6: =E4-E5 -> 2463 | F6: =F4-F5 -> 1725 | G6: =G4-G5 -> 3344 | H6: =H4-H5 -> 4882 | I6: =I4-I5 -> 5292 | ... K6: =K4-K5 -> 8355 | L6: =SUM(Quarters!H6:K6) -> 8356 | M6: =M4*M24 -> 12324.391 | N6: =N4*N24 -> 10306.076
A7: Other Income | B7: ='Data Sheet'!B25 -> -42.38 | C7: ='Data Sheet'!C25 -> 69.93 | D7: ='Data Sheet'!D25 -> 178.48 | E7: ='Data Sheet'!E25 -> 153 | F7: ='Data Sheet'!F25 -> 180 | G7: ='Data Sheet'!G25 -> 177 | H7: ='Data Sheet'!H25 -> 306 | I7: ='Data Sheet'!I25 -> 534 | ... K7: ='Data Sheet'!K25 -> 452 | L7: =SUM(Quarters!H7:K7) -> 452 | M7: 0 | N7: 0
A8: Depreciation | B8: ='Data Sheet'!B26 -> 110.53 | C8: ='Data Sheet'!C26 -> 131.43 | D8: ='Data Sheet'!D26 -> 162.84 | E8: ='Data Sheet'!E26 -> 348 | F8: ='Data Sheet'!F26 -> 375 | G8: ='Data Sheet'!G26 -> 399 | H8: ='Data Sheet'!H26 -> 441 | I8: ='Data Sheet'!I26 -> 584 | ... K8: ='Data Sheet'!K26 -> 826 | L8: =SUM(Quarters!H8:K8) -> 826 | M8: =+$L8 -> 826 | N8: =+$L8 -> 826
A9: Interest | B9: ='Data Sheet'!B27 -> 37.74 | C9: ='Data Sheet'!C27 -> 52.92 | D9: ='Data Sheet'!D27 -> 52.54 | E9: ='Data Sheet'!E27 -> 166 | F9: ='Data Sheet'!F27 -> 203 | G9: ='Data Sheet'!G27 -> 218 | H9: ='Data Sheet'!H27 -> 300 | I9: ='Data Sheet'!I27 -> 619 | ... K9: ='Data Sheet'!K27 -> 1180 | L9: =SUM(Quarters!H9:K9) -> 1180 | M9: =+$L9 -> 1180 | N9: =+$L9 -> 1180
A10: Profit before tax | B10: ='Data Sheet'!B28 -> 973.25 | C10: ='Data Sheet'!C28 -> 1529.78 | D10: ='Data Sheet'!D28 -> 1956.89 | E10: ='Data Sheet'!E28 -> 2102 | F10: ='Data Sheet'!F28 -> 1327 | G10: ='Data Sheet'!G28 -> 2904 | H10: ='Data Sheet'!H28 -> 4447 | I10: ='Data Sheet'!I28 -> 4623 | ... K10: ='Data Sheet'!K28 -> 6801 | L10: =SUM(Quarters!H10:K10) -> 6802 | M10: =M6+M7-SUM(M8:M9) -> 10318.391 | N10: =N6+N7-SUM(N8:N9) -> 8300.0757
A11: Tax | B11: ='Data Sheet'!B29 -> 275.97 | C11: ='Data Sheet'!C29 -> 427.87 | D11: ='Data Sheet'!D29 -> 568.24 | E11: ='Data Sheet'!E29 -> 609 | F11: ='Data Sheet'!F29 -> 353 | G11: ='Data Sheet'!G29 -> 706 | H11: ='Data Sheet'!H29 -> 1173 | I11: ='Data Sheet'!I29 -> 1127 | ... K11: ='Data Sheet'!K29 -> 1728 | L11: =SUM(Quarters!H11:K11) -> 1728 | M11: =IF($L10>0,$L11/$L10,0) -> 0.25404293 | N11: =IF($L10>0,$L11/$L10,0) -> 0.25404293
A12: Net profit | B12: ='Data Sheet'!B30 -> 711.47 | C12: ='Data Sheet'!C30 -> 1130.09 | D12: ='Data Sheet'!D30 -> 1404.15 | E12: ='Data Sheet'!E30 -> 1501 | F12: ='Data Sheet'!F30 -> 973 | G12: ='Data Sheet'!G30 -> 2173 | H12: ='Data Sheet'!H30 -> 3250 | I12: ='Data Sheet'!I30 -> 3496 | ... K12: ='Data Sheet'!K30 -> 5073 | L12: =SUM(Quarters!H12:K12) -> 5074 | M12: =M10-M11*M10 -> 7697.0765 | N12: =N10-N11*N10 -> 6191.5002
A13: EPS | B13: =IF('Data Sheet'!B93>0,B12/'Data Sheet'!B93,0) -> 8.0138545 | C13: =IF('Data Sheet'!C93>0,C12/'Data Sheet'!C93,0) -> 12.729106 | D13: =IF('Data Sheet'!D93>0,D12/'Data Sheet'!D93,0) -> 15.816062 | E13: =IF('Data Sheet'!E93>0,E12/'Data Sheet'!E93,0) -> 16.906961 | F13: =IF('Data Sheet'!F93>0,F12/'Data Sheet'!F93,0) -> 10.959676 | G13: =IF('Data Sheet'!G93>0,G12/'Data Sheet'!G93,0) -> 24.476233 | H13: =IF('Data Sheet'!H93>0,H12/'Data Sheet'!H93,0) -> 36.607344 | I13: =IF('Data Sheet'!I93>0,I12/'Data Sheet'!I93,0) -> 39.378238 | ... K13: =IF('Data Sheet'!K93>0,K12/'Data Sheet'!K93,0) -> 57.141248 | L13: =IF('Data Sheet'!$B6>0,'Profit & Loss'!L12/'Data Sheet'!$B6,0) -> 57.153399 | M13: =IF('Data Sheet'!$B6>0,'Profit & Loss'!M12/'Data Sheet'!$B6,0) -> 86.699662 | N13: =IF('Data Sheet'!$B6>0,'Profit & Loss'!N12/'Data Sheet'!$B6,0) -> 69.74089
A14: Price to earning | B14: =IF(B15>0,B15/B13,"") -> 57.743749 | C14: =IF(C15>0,C15/C13,"") -> 74.027196 | D14: =IF(D15>0,D15/D13,"") -> 72.195594 | E14: =IF(E15>0,E15/E13,"") -> 55.225773 | F14: =IF(F15>0,F15/F13,"") -> 142.16205 | G14: =IF(G15>0,G15/G13,"") -> 103.61684 | H14: =IF(H15>0,H15/H13,"") -> 68.69933 | I14: =IF(I15>0,I15/I13,"") -> 96.545711 | ... K14: =IF(K15>0,K15/K13,"") -> 69.151447 | L14: =IF(L13>0,L15/L13,0) -> 77.156391 | M14: =M25 -> 81.088291 | N14: =N25 -> 77.156391
A15: Price | B15: ='Data Sheet'!B90 -> 462.75 | C15: ='Data Sheet'!C90 -> 942.3 | D15: ='Data Sheet'!D90 -> 1141.85 | E15: ='Data Sheet'!E90 -> 933.7 | F15: ='Data Sheet'!F90 -> 1558.05 | G15: ='Data Sheet'!G90 -> 2536.15 | H15: ='Data Sheet'!H90 -> 2514.9 | I15: ='Data Sheet'!I90 -> 3801.8 | ... K15: ='Data Sheet'!K90 -> 3951.4 | L15: ='Data Sheet'!B8 -> 4409.75 | M15: =M13*M14 -> 7030.3274 | N15: =N13*N14 -> 5380.9554
A17: RATIOS:
A18: Dividend Payout | B18: =IF('Data Sheet'!B30>0, 'Data Sheet'!B31/'Data Sheet'!B30, 0) -> 0.32444095 | C18: =IF('Data Sheet'!C30>0, 'Data Sheet'!C31/'Data Sheet'!C30, 0) -> 0.29459601 | D18: =IF('Data Sheet'!D30>0, 'Data Sheet'!D31/'Data Sheet'!D30, 0) -> 0.31613432 | E18: =IF('Data Sheet'!E30>0, 'Data Sheet'!E31/'Data Sheet'!E30, 0) -> 0.23717522 | F18: =IF('Data Sheet'!F30>0, 'Data Sheet'!F31/'Data Sheet'!F30, 0) -> 0.36587873 | G18: =IF('Data Sheet'!G30>0, 'Data Sheet'!G31/'Data Sheet'!G30, 0) -> 0.30717902 | H18: =IF('Data Sheet'!H30>0, 'Data Sheet'!H31/'Data Sheet'!H30, 0) -> 0.27384615 | I18: =IF('Data Sheet'!I30>0, 'Data Sheet'!I31/'Data Sheet'!I30, 0) -> 0.28003432 | ... K18: =IF('Data Sheet'!K30>0, 'Data Sheet'!K31/'Data Sheet'!K30, 0) -> 0.26315789
A19: OPM | B19: =IF(B6>0,B6/B4,0) -> 0.08776977 | C19: =IF(C6>0,C6/C4,0) -> 0.10199897 | D19: =IF(D6>0,D6/D4,0) -> 0.10080582 | E19: =IF(E6>0,E6/E4,0) -> 0.11699601 | F19: =IF(F6>0,F6/F4,0) -> 0.079698762 | G19: =IF(G6>0,G6/G4,0) -> 0.11611514 | H19: =IF(H6>0,H6/H4,0) -> 0.12032039 | I19: =IF(I6>0,I6/I4,0) -> 0.10359408 | ... L19: =IF(L6>0,L6/L4,0) -> 0.095405554
G22: TRENDS: | H22: 10 YEARS | I22: 7 YEARS | J22: 5 YEARS | K22: 3 YEARS | L22: RECENT | M22: BEST | N22: WORST
G23: Sales Growth | H23: =IF(B4=0,"",POWER($K4/B4,1/9)-1) -> 0.2333743 | I23: =IF(D4=0,"",POWER($K4/D4,1/7)-1) -> 0.23685478 | J23: =IF(F4=0,"",POWER($K4/F4,1/5)-1) -> 0.32256629 | K23: =IF(H4=0,"",POWER($K4/H4, 1/3)-1) -> 0.2923756 | L23: =IF(ISERROR(MAX(IF(J4=0,"",(K4-J4)/J4),IF(K4=0,"",(L4-K4)/K4))),"",MAX(IF(J4=0,"",(K4-J4)/J4),IF(K4=0,"",(L4-K4)/K4))) -> 0.44872304 | M23: =MAX(K23:L23) -> 0.44872304 | N23: =MIN(H23:L23) -> 0.2333743
G24: OPM | H24: =IF(SUM(B4:$K$4)=0,"",SUMPRODUCT(B19:$K$19,B4:$K$4)/SUM(B4:$K$4)) -> 0.10144741 | I24: =IF(SUM(E4:$K$4)=0,"",SUMPRODUCT(E19:$K$19,E4:$K$4)/SUM(E4:$K$4)) -> 0.10204246 | J24: =IF(SUM(G4:$K$4)=0,"",SUMPRODUCT(G19:$K$19,G4:$K$4)/SUM(G4:$K$4)) -> 0.10267116 | K24: =IF(SUM(I4:$K$4)=0, "", SUMPRODUCT(I19:$K$19,I4:$K$4)/SUM(I4:$K$4)) -> 0.097130431 | L24: =L19 -> 0.095405554 | M24: =MAX(K24:L24) -> 0.097130431 | N24: =MIN(H24:L24) -> 0.095405554
G25: Price to Earning | H25: =IF(ISERROR(AVERAGEIF(B14:$L14,">0")),"",AVERAGEIF(B14:$L14,">0")) -> 81.638518 | I25: =IF(ISERROR(AVERAGEIF(E14:$L14,">0")),"",AVERAGEIF(E14:$L14,">0")) -> 86.757145 | J25: =IF(ISERROR(AVERAGEIF(G14:$L14,">0")),"",AVERAGEIF(G14:$L14,">0")) -> 82.778223 | K25: =IF(ISERROR(AVERAGEIF(I14:$L14,">0")),"",AVERAGEIF(I14:$L14,">0")) -> 81.088291 | L25: =L14 -> 77.156391 | M25: =MAX(K25:L25) -> 81.088291 | N25: =MIN(H25:L25) -> 77.156391

Sheet Quarters
A1: ='Profit & Loss'!A1 -> TITAN COMPANY LTD | E1: =UPDATE | J1: SCREENER.IN
A3: Narration | B3: ='Data Sheet'!B41 -> 45291 | C3: ='Data Sheet'!C41 -> 45382 | D3: ='Data Sheet'!D41 -> 45473 | E3: ='Data Sheet'!E41 -> 45565 | F3: ='Data Sheet'!F41 -> 45657 | G3: ='Data Sheet'!G41 -> 45747 | H3: ='Data Sheet'!H41 -> 45838 | I3: ='Data Sheet'!I41 -> 45930 | ... K3: ='Data Sheet'!K41 -> 46112
A4: Sales | B4: ='Data Sheet'!B42 -> 14164 | C4: ='Data Sheet'!C42 -> 12494 | D4: ='Data Sheet'!D42 -> 13266 | E4: ='Data Sheet'!E42 -> 14534 | F4: ='Data Sheet'!F42 -> 17740 | G4: ='Data Sheet'!G42 -> 14916 | H4: ='Data Sheet'!H42 -> 16523 | I4: ='Data Sheet'!I42 -> 18725 | ... K4: ='Data Sheet'!K42 -> 26920
A5: Expenses | B5: ='Data Sheet'!B43 -> 12599 | C5: ='Data Sheet'!C43 -> 11303 | D5: ='Data Sheet'!D43 -> 12019 | E5: ='Data Sheet'!E43 -> 13298 | F5: ='Data Sheet'!F43 -> 16066 | G5: ='Data Sheet'!G43 -> 13379 | H5: ='Data Sheet'!H43 -> 14693 | I5: ='Data Sheet'!I43 -> 16850 | ... K5: ='Data Sheet'!K43 -> 24982
A6: Operating Profit | B6: ='Data Sheet'!B50 -> 1565 | C6: ='Data Sheet'!C50 -> 1191 | D6: ='Data Sheet'!D50 -> 1247 | E6: ='Data Sheet'!E50 -> 1236 | F6: ='Data Sheet'!F50 -> 1674 | G6: ='Data Sheet'!G50 -> 1537 | H6: ='Data Sheet'!H50 -> 1830 | I6: ='Data Sheet'!I50 -> 1875 | ... K6: ='Data Sheet'!K50 -> 1938
A7: Other Income | B7: ='Data Sheet'!B44 -> 136 | C7: ='Data Sheet'!C44 -> 159 | D7: ='Data Sheet'!D44 -> 120 | E7: ='Data Sheet'!E44 -> 123 | F7: ='Data Sheet'!F44 -> 128 | G7: ='Data Sheet'!G44 -> 116 | H7: ='Data Sheet'!H44 -> 105 | I7: ='Data Sheet'!I44 -> 113 | ... K7: ='Data Sheet'!K44 -> 235
A8: Depreciation | B8: ='Data Sheet'!B45 -> 154 | C8: ='Data Sheet'!C45 -> 158 | D8: ='Data Sheet'!D45 -> 164 | E8: ='Data Sheet'!E45 -> 171 | F8: ='Data Sheet'!F45 -> 175 | G8: ='Data Sheet'!G45 -> 183 | H8: ='Data Sheet'!H45 -> 184 | I8: ='Data Sheet'!I45 -> 189 | ... K8: ='Data Sheet'!K45 -> 246
A9: Interest | B9: ='Data Sheet'!B46 -> 169 | C9: ='Data Sheet'!C46 -> 201 | D9: ='Data Sheet'!D46 -> 230 | E9: ='Data Sheet'!E46 -> 240 | F9: ='Data Sheet'!F46 -> 231 | G9: ='Data Sheet'!G46 -> 252 | H9: ='Data Sheet'!H46 -> 271 | I9: ='Data Sheet'!I46 -> 277 | ... K9: ='Data Sheet'!K46 -> 350
A10: Profit before tax | B10: ='Data Sheet'!B47 -> 1378 | C10: ='Data Sheet'!C47 -> 991 | D10: ='Data Sheet'!D47 -> 973 | E10: ='Data Sheet'!E47 -> 948 | F10: ='Data Sheet'!F47 -> 1396 | G10: ='Data Sheet'!G47 -> 1218 | H10: ='Data Sheet'!H47 -> 1480 | I10: ='Data Sheet'!I47 -> 1522 | ... K10: ='Data Sheet'!K47 -> 1577
A11: Tax | B11: ='Data Sheet'!B48 -> 325 | C11: ='Data Sheet'!C48 -> 220 | D11: ='Data Sheet'!D48 -> 258 | E11: ='Data Sheet'!E48 -> 244 | F11: ='Data Sheet'!F48 -> 349 | G11: ='Data Sheet'!G48 -> 347 | H11: ='Data Sheet'!H48 -> 389 | I11: ='Data Sheet'!I48 -> 402 | ... K11: ='Data Sheet'!K48 -> 398
A12: Net profit | B12: ='Data Sheet'!B49 -> 1053 | C12: ='Data Sheet'!C49 -> 771 | D12: ='Data Sheet'!D49 -> 715 | E12: ='Data Sheet'!E49 -> 704 | F12: ='Data Sheet'!F49 -> 1047 | G12: ='Data Sheet'!G49 -> 871 | H12: ='Data Sheet'!H49 -> 1091 | I12: ='Data Sheet'!I49 -> 1120 | ... K12: ='Data Sheet'!K49 -> 1179
A14: OPM | B14: =IF(B4>0,B6/B4,"") -> 0.11049139 | C14: =IF(C4>0,C6/C4,"") -> 0.095325756 | D14: =IF(D4>0,D6/D4,"") -> 0.093999698 | E14: =IF(E4>0,E6/E4,"") -> 0.085041971 | F14: =IF(F4>0,F6/F4,"") -> 0.094363021 | G14: =IF(G4>0,G6/G4,"") -> 0.10304371 | H14: =IF(H4>0,H6/H4,"") -> 0.11075471 | I14: =IF(I4>0,I6/I4,"") -> 0.10013351 | ... K14: =IF(K4>0,K6/K4,"") -> 0.071991085

Sheet Balance Sheet
A1: ='Profit & Loss'!A1 -> TITAN COMPANY LTD | E1: =UPDATE | J1: SCREENER.IN
A3: Narration | B3: ='Data Sheet'!B56 -> 42825 | C3: ='Data Sheet'!C56 -> 43190 | D3: ='Data Sheet'!D56 -> 43555 | E3: ='Data Sheet'!E56 -> 43921 | F3: ='Data Sheet'!F56 -> 44286 | G3: ='Data Sheet'!G56 -> 44651 | H3: ='Data Sheet'!H56 -> 45016 | I3: ='Data Sheet'!I56 -> 45382 | ... K3: ='Data Sheet'!K56 -> 46112
A4: Equity Share Capital | B4: ='Data Sheet'!B57 -> 88.78 | C4: ='Data Sheet'!C57 -> 88.78 | D4: ='Data Sheet'!D57 -> 88.78 | E4: ='Data Sheet'!E57 -> 89 | F4: ='Data Sheet'!F57 -> 89 | G4: ='Data Sheet'!G57 -> 89 | H4: ='Data Sheet'!H57 -> 89 | I4: ='Data Sheet'!I57 -> 89 | ... K4: ='Data Sheet'!K57 -> 89
A5: Reserves | B5: ='Data Sheet'!B58 -> 4143.6 | C5: ='Data Sheet'!C58 -> 5001.1 | D5: ='Data Sheet'!D58 -> 5981.37 | E5: ='Data Sheet'!E58 -> 6580 | F5: ='Data Sheet'!F58 -> 7408 | G5: ='Data Sheet'!G58 -> 9214 | H5: ='Data Sheet'!H58 -> 11762 | I5: ='Data Sheet'!I58 -> 9304 | ... K5: ='Data Sheet'!K58 -> 15614
A6: Borrowings | B6: ='Data Sheet'!B59 -> 1882.43 | C6: ='Data Sheet'!C59 -> 1691.01 | D6: ='Data Sheet'!D59 -> 2392.98 | E6: ='Data Sheet'!E59 -> 3562 | F6: ='Data Sheet'!F59 -> 5638 | G6: ='Data Sheet'!G59 -> 7275 | H6: ='Data Sheet'!H59 -> 9367 | I6: ='Data Sheet'!I59 -> 15528 | ... K6: ='Data Sheet'!K59 -> 14551
A7: Other Liabilities | B7: ='Data Sheet'!B60 -> 2292.76 | C7: ='Data Sheet'!C60 -> 2740.15 | D7: ='Data Sheet'!D60 -> 3246.71 | E7: ='Data Sheet'!E60 -> 3313 | F7: ='Data Sheet'!F60 -> 3309 | G7: ='Data Sheet'!G60 -> 4610 | H7: ='Data Sheet'!H60 -> 5802 | I7: ='Data Sheet'!I60 -> 6626 | ... K7: ='Data Sheet'!K60 -> 30307
A8: Total | B8: ='Data Sheet'!B61 -> 8407.57 | C8: ='Data Sheet'!C61 -> 9521.04 | D8: ='Data Sheet'!D61 -> 11709.84 | E8: ='Data Sheet'!E61 -> 13544 | F8: ='Data Sheet'!F61 -> 16444 | G8: ='Data Sheet'!G61 -> 21188 | H8: ='Data Sheet'!H61 -> 27020 | I8: ='Data Sheet'!I61 -> 31547 | ... K8: ='Data Sheet'!K61 -> 60561
A10: Net Block | B10: ='Data Sheet'!B62 -> 1188.72 | C10: ='Data Sheet'!C62 -> 1473.81 | D10: ='Data Sheet'!D62 -> 1566.63 | E10: ='Data Sheet'!E62 -> 2633 | F10: ='Data Sheet'!F62 -> 2523 | G10: ='Data Sheet'!G62 -> 2544 | H10: ='Data Sheet'!H62 -> 2998 | I10: ='Data Sheet'!I62 -> 3709 | ... K10: ='Data Sheet'!K62 -> 6906
A11: Capital Work in Progress | B11: ='Data Sheet'!B63 -> 152.07 | C11: ='Data Sheet'!C63 -> 43.37 | D11: ='Data Sheet'!D63 -> 31.77 | E11: ='Data Sheet'!E63 -> 18 | F11: ='Data Sheet'!F63 -> 32 | G11: ='Data Sheet'!G63 -> 85 | H11: ='Data Sheet'!H63 -> 144 | I11: ='Data Sheet'!I63 -> 97 | ... K11: ='Data Sheet'!K63 -> 135
A12: Investments | B12: ='Data Sheet'!B64 -> 430.73 | C12: ='Data Sheet'!C64 -> 35.99 | D12: ='Data Sheet'!D64 -> 108.42 | E12: ='Data Sheet'!E64 -> 158 | F12: ='Data Sheet'!F64 -> 2824 | G12: ='Data Sheet'!G64 -> 294 | H12: ='Data Sheet'!H64 -> 2515 | I12: ='Data Sheet'!I64 -> 2345 | ... K12: ='Data Sheet'!K64 -> 3506
A13: Other Assets | B13: ='Data Sheet'!B65 -> 6636.05 | C13: ='Data Sheet'!C65 -> 7967.87 | D13: ='Data Sheet'!D65 -> 10003.02 | E13: ='Data Sheet'!E65 -> 10735 | F13: ='Data Sheet'!F65 -> 11065 | G13: ='Data Sheet'!G65 -> 18265 | H13: ='Data Sheet'!H65 -> 21363 | I13: ='Data Sheet'!I65 -> 25396 | ... K13: ='Data Sheet'!K65 -> 50014
A14: Total | B14: ='Data Sheet'!B66 -> 8407.57 | C14: ='Data Sheet'!C66 -> 9521.04 | D14: ='Data Sheet'!D66 -> 11709.84 | E14: ='Data Sheet'!E66 -> 13544 | F14: ='Data Sheet'!F66 -> 16444 | G14: ='Data Sheet'!G66 -> 21188 | H14: ='Data Sheet'!H66 -> 27020 | I14: ='Data Sheet'!I66 -> 31547 | ... K14: ='Data Sheet'!K66 -> 60561
A16: Working Capital | B16: =B13-B7 -> 4343.29 | C16: =C13-C7 -> 5227.72 | D16: =D13-D7 -> 6756.31 | E16: =E13-E7 -> 7422 | F16: =F13-F7 -> 7756 | G16: =G13-G7 -> 13655 | H16: =H13-H7 -> 15561 | I16: =I13-I7 -> 18770 | ... K16: =K13-K7 -> 19707
A17: Debtors | B17: ='Data Sheet'!B67 -> 207.6 | C17: ='Data Sheet'!C67 -> 295.69 | D17: ='Data Sheet'!D67 -> 420.45 | E17: ='Data Sheet'!E67 -> 312 | F17: ='Data Sheet'!F67 -> 366 | G17: ='Data Sheet'!G67 -> 565 | H17: ='Data Sheet'!H67 -> 674 | I17: ='Data Sheet'!I67 -> 1018 | ... K17: ='Data Sheet'!K67 -> 916
A18: Inventory | B18: ='Data Sheet'!B68 -> 4925.74 | C18: ='Data Sheet'!C68 -> 5924.84 | D18: ='Data Sheet'!D68 -> 7038.82 | E18: ='Data Sheet'!E68 -> 8103 | F18: ='Data Sheet'!F68 -> 8408 | G18: ='Data Sheet'!G68 -> 13609 | H18: ='Data Sheet'!H68 -> 16584 | I18: ='Data Sheet'!I68 -> 19051 | ... K18: ='Data Sheet'!K68 -> 42743
A20: Debtor Days | B20: =IF('Profit & Loss'!B4>0,'Balance Sheet'!B17/('Profit & Loss'!B4/365),0) -> 5.714122 | C20: =IF('Profit & Loss'!C4>0,'Balance Sheet'!C17/('Profit & Loss'!C4/365),0) -> 6.6953095 | D20: =IF('Profit & Loss'!D4>0,'Balance Sheet'!D17/('Profit & Loss'!D4/365),0) -> 7.7591372 | E20: =IF('Profit & Loss'!E4>0,'Balance Sheet'!E17/('Profit & Loss'!E4/365),0) -> 5.4094623 | F20: =IF('Profit & Loss'!F4>0,'Balance Sheet'!F17/('Profit & Loss'!F4/365),0) -> 6.1721493 | G20: =IF('Profit & Loss'!G4>0,'Balance Sheet'!G17/('Profit & Loss'!G4/365),0) -> 7.1608389 | H20: =IF('Profit & Loss'!H4>0,'Balance Sheet'!H17/('Profit & Loss'!H4/365),0) -> 6.063093 | I20: =IF('Profit & Loss'!I4>0,'Balance Sheet'!I17/('Profit & Loss'!I4/365),0) -> 7.2737061 | ... K20: =IF('Profit & Loss'!K4>0,'Balance Sheet'!K17/('Profit & Loss'!K4/365),0) -> 3.8173639
A21: Inventory Turnover | B21: =IF('Balance Sheet'!B18>0,'Profit & Loss'!B4/'Balance Sheet'!B18,0) -> 2.6921498 | C21: =IF('Balance Sheet'!C18>0,'Profit & Loss'!C4/'Balance Sheet'!C18,0) -> 2.7207098 | D21: =IF('Balance Sheet'!D18>0,'Profit & Loss'!D4/'Balance Sheet'!D18,0) -> 2.8099198 | E21: =IF('Balance Sheet'!E18>0,'Profit & Loss'!E4/'Balance Sheet'!E18,0) -> 2.5980501 | F21: =IF('Balance Sheet'!F18>0,'Profit & Loss'!F4/'Balance Sheet'!F18,0) -> 2.574215 | G21: =IF('Balance Sheet'!G18>0,'Profit & Loss'!G4/'Balance Sheet'!G18,0) -> 2.1161731 | H21: =IF('Balance Sheet'!H18>0,'Profit & Loss'!H4/'Balance Sheet'!H18,0) -> 2.4466353 | I21: =IF('Balance Sheet'!I18>0,'Profit & Loss'!I4/'Balance Sheet'!I18,0) -> 2.681434 | ... K21: =IF('Balance Sheet'!K18>0,'Profit & Loss'!K4/'Balance Sheet'!K18,0) -> 2.0490841
A23: Return on Equity | B23: =IF(SUM('Balance Sheet'!B4:B5)>0,'Profit & Loss'!B12/SUM('Balance Sheet'!B4:B5),"") -> 0.16810164 | C23: =IF(SUM('Balance Sheet'!C4:C5)>0,'Profit & Loss'!C12/SUM('Balance Sheet'!C4:C5),"") -> 0.22202685 | D23: =IF(SUM('Balance Sheet'!D4:D5)>0,'Profit & Loss'!D12/SUM('Balance Sheet'!D4:D5),"") -> 0.23132048 | E23: =IF(SUM('Balance Sheet'!E4:E5)>0,'Profit & Loss'!E12/SUM('Balance Sheet'!E4:E5),"") -> 0.22507123 | F23: =IF(SUM('Balance Sheet'!F4:F5)>0,'Profit & Loss'!F12/SUM('Balance Sheet'!F4:F5),"") -> 0.12978525 | G23: =IF(SUM('Balance Sheet'!G4:G5)>0,'Profit & Loss'!G12/SUM('Balance Sheet'!G4:G5),"") -> 0.23358057 | H23: =IF(SUM('Balance Sheet'!H4:H5)>0,'Profit & Loss'!H12/SUM('Balance Sheet'!H4:H5),"") -> 0.27423846 | I23: =IF(SUM('Balance Sheet'!I4:I5)>0,'Profit & Loss'!I12/SUM('Balance Sheet'!I4:I5),"") -> 0.37219206 | ... K23: =IF(SUM('Balance Sheet'!K4:K5)>0,'Profit & Loss'!K12/SUM('Balance Sheet'!K4:K5),"") -> 0.32305929
A24: Return on Capital Emp | C24: =IF((B4+B5+B6+C4+C5+C6)>0,('Profit & Loss'!C10+'Profit & Loss'!C9)*2/(B4+B5+B6+C4+C5+C6),"") -> 0.24546167 | D24: =IF((C4+C5+C6+D4+D5+D6)>0,('Profit & Loss'!D10+'Profit & Loss'!D9)*2/(C4+C5+C6+D4+D5+D6),"") -> 0.26363518 | E24: =IF((D4+D5+D6+E4+E5+E6)>0,('Profit & Loss'!E10+'Profit & Loss'!E9)*2/(D4+D5+D6+E4+E5+E6),"") -> 0.24264301 | F24: =IF((E4+E5+E6+F4+F5+F6)>0,('Profit & Loss'!F10+'Profit & Loss'!F9)*2/(E4+E5+E6+F4+F5+F6),"") -> 0.13095951 | G24: =IF((F4+F5+F6+G4+G5+G6)>0,('Profit & Loss'!G10+'Profit & Loss'!G9)*2/(F4+F5+F6+G4+G5+G6),"") -> 0.21014371 | H24: =IF((G4+G5+G6+H4+H5+H6)>0,('Profit & Loss'!H10+'Profit & Loss'!H9)*2/(G4+G5+G6+H4+H5+H6),"") -> 0.2511906 | I24: =IF((H4+H5+H6+I4+I5+I6)>0,('Profit & Loss'!I10+'Profit & Loss'!I9)*2/(H4+H5+H6+I4+I5+I6),"") -> 0.22722642 | J24: =IF((I4+I5+I6+J4+J5+J6)>0,('Profit & Loss'!J10+'Profit & Loss'!J9)*2/(I4+I5+I6+J4+J5+J6),"") -> 0.19147971 | K24: =IF((J4+J5+J6+K4+K5+K6)>0,('Profit & Loss'!K10+'Profit & Loss'!K9)*2/(J4+J5+J6+K4+K5+K6),"") -> 0.25476019

Sheet Cash Flow
A1: ='Balance Sheet'!A1 -> TITAN COMPANY LTD | E1: =UPDATE | J1: SCREENER.IN
A3: Narration | B3: ='Data Sheet'!B81 -> 42825 | C3: ='Data Sheet'!C81 -> 43190 | D3: ='Data Sheet'!D81 -> 43555 | E3: ='Data Sheet'!E81 -> 43921 | F3: ='Data Sheet'!F81 -> 44286 | G3: ='Data Sheet'!G81 -> 44651 | H3: ='Data Sheet'!H81 -> 45016 | I3: ='Data Sheet'!I81 -> 45382 | ... K3: ='Data Sheet'!K81 -> 46112
A4: Cash from Operating Activity | B4: ='Data Sheet'!B82 -> 1712.3 | C4: ='Data Sheet'!C82 -> -51.12 | D4: ='Data Sheet'!D82 -> 1242.92 | E4: ='Data Sheet'!E82 -> -348 | F4: ='Data Sheet'!F82 -> 4139 | G4: ='Data Sheet'!G82 -> -724 | H4: ='Data Sheet'!H82 -> 1370 | I4: ='Data Sheet'!I82 -> 1695 | ... K4: ='Data Sheet'!K82 -> 5590
A5: Cash from Investing Activity | B5: ='Data Sheet'!B83 -> -953.15 | C5: ='Data Sheet'!C83 -> 97.62 | D5: ='Data Sheet'!D83 -> -796.61 | E5: ='Data Sheet'!E83 -> 235 | F5: ='Data Sheet'!F83 -> -2799 | G5: ='Data Sheet'!G83 -> 1165 | H5: ='Data Sheet'!H83 -> -1814 | I5: ='Data Sheet'!I83 -> -189 | ... K5: ='Data Sheet'!K83 -> -2934
A6: Cash from Financing Activity | B6: ='Data Sheet'!B84 -> -165.6 | C6: ='Data Sheet'!C84 -> -252.45 | D6: ='Data Sheet'!D84 -> -488.83 | E6: ='Data Sheet'!E84 -> -242 | F6: ='Data Sheet'!F84 -> -1234 | G6: ='Data Sheet'!G84 -> -403 | H6: ='Data Sheet'!H84 -> 457 | I6: ='Data Sheet'!I84 -> -1329 | ... K6: ='Data Sheet'!K84 -> -2159
A7: Net Cash Flow | B7: ='Data Sheet'!B85 -> 593.55 | C7: ='Data Sheet'!C85 -> -205.95 | D7: ='Data Sheet'!D85 -> -42.52 | E7: ='Data Sheet'!E85 -> -355 | F7: ='Data Sheet'!F85 -> 106 | G7: ='Data Sheet'!G85 -> 38 | H7: ='Data Sheet'!H85 -> 13 | I7: ='Data Sheet'!I85 -> 177 | ... K7: ='Data Sheet'!K85 -> 497

Sheet Customization
A1: How to use it?
A3: You can customize this workbook as you want.
B4: You can add custom formating, add conditional formating, add your own formulas… do ANYTHING.
B5: Please don't edit the "Data Sheet" only.
A7: After customization, you can upload this back on Screener.
B8: Upload on: | C8: https://www.screener.in/excel/
A10: Download your customized workbooks now onwards.
B11: Now whenever you will "Export to excel" from Screener, it will export your customized file.
A14: TESTING:
B15: This is a testing feature currently.
B16: You can report any formula errors on the worksheet at: support@screener.in

Sheet financials>

Sheet Historical FS
B2: ="Historical Financial statement - "&'Data Sheet'!B1 -> Historical Financial statement - TITAN COMPANY LTD
B3: Years | C3: ='Data Sheet'!B16 -> 42825 | D3: ='Data Sheet'!C16 -> 43190 | E3: ='Data Sheet'!D16 -> 43555 | F3: ='Data Sheet'!E16 -> 43921 | G3: ='Data Sheet'!F16 -> 44286 | H3: ='Data Sheet'!G16 -> 44651 | I3: ='Data Sheet'!H16 -> 45016 | J3: ='Data Sheet'!I16 -> 45382 | ... L3: ='Data Sheet'!K16 -> 46112 | M3: LTM
A5: # | B5: Income statement
B6: Sales | C6: =IFERROR('Data Sheet'!B17,0) -> 13260.83 | D6: =IFERROR('Data Sheet'!C17,0) -> 16119.77 | E6: =IFERROR('Data Sheet'!D17,0) -> 19778.52 | F6: =IFERROR('Data Sheet'!E17,0) -> 21052 | G6: =IFERROR('Data Sheet'!F17,0) -> 21644 | H6: =IFERROR('Data Sheet'!G17,0) -> 28799 | I6: =IFERROR('Data Sheet'!H17,0) -> 40575 | J6: =IFERROR('Data Sheet'!I17,0) -> 51084 | ... L6: =IFERROR('Data Sheet'!K17,0) -> 87584 | M6: =IFERROR(SUM('Data Sheet'!H42:K42),0) -> 87584
B7: Sales Growth | C7: - | D7: =IFERROR(D6/C6-1,0) -> 0.21559284 | E7: =IFERROR(E6/D6-1,0) -> 0.22697284 | F7: =IFERROR(F6/E6-1,0) -> 0.064387022 | G7: =IFERROR(G6/F6-1,0) -> 0.028120844 | H7: =IFERROR(H6/G6-1,0) -> 0.3305766 | I7: =IFERROR(I6/H6-1,0) -> 0.40890309 | J7: =IFERROR(J6/I6-1,0) -> 0.25900185 | K7: =IFERROR(K6/J6-1,0) -> 0.18346253 | ... M7: =IFERROR(M6/L6-1,0) -> 0
B9: COGS | C9: =IFERROR(SUM('Data Sheet'!B18,'Data Sheet'!B20:B22)-1*'Data Sheet'!B19,0) -> 10606.01 | D9: =IFERROR(SUM('Data Sheet'!C18,'Data Sheet'!C20:C22)-1*'Data Sheet'!C19,0) -> 12762.63 | E9: =IFERROR(SUM('Data Sheet'!D18,'Data Sheet'!D20:D22)-1*'Data Sheet'!D19,0) -> 15660.48 | F9: =IFERROR(SUM('Data Sheet'!E18,'Data Sheet'!E20:E22)-1*'Data Sheet'!E19,0) -> 16626 | G9: =IFERROR(SUM('Data Sheet'!F18,'Data Sheet'!F20:F22)-1*'Data Sheet'!F19,0) -> 17661 | H9: =IFERROR(SUM('Data Sheet'!G18,'Data Sheet'!G20:G22)-1*'Data Sheet'!G19,0) -> 23225 | I9: =IFERROR(SUM('Data Sheet'!H18,'Data Sheet'!H20:H22)-1*'Data Sheet'!H19,0) -> 32295 | J9: =IFERROR(SUM('Data Sheet'!I18,'Data Sheet'!I20:I22)-1*'Data Sheet'!I19,0) -> 41664 | ... L9: =IFERROR(SUM('Data Sheet'!K18,'Data Sheet'!K20:K22)-1*'Data Sheet'!K19,0) -> 72988 | M9: =IFERROR(SUM('Data Sheet'!H43:K43),0) -> 79228
B10: COSG % Sales | C10: =C9/C6 -> 0.79979986 | D10: =D9/D6 -> 0.79173772 | E10: =E9/E6 -> 0.79179231 | F10: =F9/F6 -> 0.78975869 | G10: =G9/G6 -> 0.81597671 | H10: =H9/H6 -> 0.80645161 | I10: =I9/I6 -> 0.79593346 | J10: =J9/J6 -> 0.81559784 | ... M10: =M9/M6 -> 0.90459445
B12: Gross Profit | C12: =C6-C9 -> 2654.82 | D12: =D6-D9 -> 3357.14 | E12: =E6-E9 -> 4118.04 | F12: =F6-F9 -> 4426 | G12: =G6-G9 -> 3983 | H12: =H6-H9 -> 5574 | I12: =I6-I9 -> 8280 | J12: =J6-J9 -> 9420 | ... M12: =M6-M9 -> 8356
B13: Gross Margin | C13: =C12/C6 -> 0.20020014 | D13: =D12/D6 -> 0.20826228 | E13: =E12/E6 -> 0.20820769 | F13: =F12/F6 -> 0.21024131 | G13: =G12/G6 -> 0.18402329 | H13: =H12/H6 -> 0.19354839 | I13: =I12/I6 -> 0.20406654 | J13: =J12/J6 -> 0.18440216 | ... M13: =M12/M6 -> 0.095405554
B15: Selling & General Exp | C15: =IFERROR(SUM('Data Sheet'!B23:B24),0) -> 1490.92 | D15: =IFERROR(SUM('Data Sheet'!C23:C24),0) -> 1712.94 | E15: =IFERROR(SUM('Data Sheet'!D23:D24),0) -> 2124.25 | F15: =IFERROR(SUM('Data Sheet'!E23:E24),0) -> 1963 | G15: =IFERROR(SUM('Data Sheet'!F23:F24),0) -> 2258 | H15: =IFERROR(SUM('Data Sheet'!G23:G24),0) -> 2230 | I15: =IFERROR(SUM('Data Sheet'!H23:H24),0) -> 3398 | J15: =IFERROR(SUM('Data Sheet'!I23:I24),0) -> 4128 | ... M15: =IFERROR(SUM('Data Sheet'!L23:L24),0) -> 0
B16: S&G Exp % Sales | C16: =C15/C6 -> 0.11243037 | D16: =D15/D6 -> 0.1062633 | E16: =E15/E6 -> 0.10740187 | F16: =F15/F6 -> 0.093245297 | G16: =G15/G6 -> 0.10432452 | H16: =H15/H6 -> 0.077433244 | I16: =I15/I6 -> 0.083746149 | J16: =J15/J6 -> 0.080808081 | ... M16: =M15/M6 -> 0
B18: EBITDA | C18: =C12-C15 -> 1163.9 | D18: =D12-D15 -> 1644.2 | E18: =E12-E15 -> 1993.79 | F18: =F12-F15 -> 2463 | G18: =G12-G15 -> 1725 | H18: =H12-H15 -> 3344 | I18: =I12-I15 -> 4882 | J18: =J12-J15 -> 5292 | ... M18: =M12-M15 -> 8356
B19: EBITDA Margin | C19: =C18/C6 -> 0.08776977 | D19: =D18/D6 -> 0.10199897 | E19: =E18/E6 -> 0.10080582 | F19: =F18/F6 -> 0.11699601 | G19: =G18/G6 -> 0.079698762 | H19: =H18/H6 -> 0.11611514 | I19: =I18/I6 -> 0.12032039 | J19: =J18/J6 -> 0.10359408 | ... M19: =M18/M6 -> 0.095405554
B21: Interest | C21: =IFERROR('Data Sheet'!B27,0) -> 37.74 | D21: =IFERROR('Data Sheet'!C27,0) -> 52.92 | E21: =IFERROR('Data Sheet'!D27,0) -> 52.54 | F21: =IFERROR('Data Sheet'!E27,0) -> 166 | G21: =IFERROR('Data Sheet'!F27,0) -> 203 | H21: =IFERROR('Data Sheet'!G27,0) -> 218 | I21: =IFERROR('Data Sheet'!H27,0) -> 300 | J21: =IFERROR('Data Sheet'!I27,0) -> 619 | ... L21: =IFERROR('Data Sheet'!K27,0) -> 1180 | M21: =IFERROR(SUM('Data Sheet'!H46:K46),0) -> 1180
B22: Interest % Sales | C22: =C21/C6 -> 0.0028459757 | D22: =D21/D6 -> 0.0032829253 | E22: =E21/E6 -> 0.0026564172 | F22: =F21/F6 -> 0.0078852366 | G22: =G21/G6 -> 0.0093790427 | H22: =H21/H6 -> 0.0075697073 | I22: =I21/I6 -> 0.0073937153 | J22: =J21/J6 -> 0.012117297 | ... M22: =M21/M6 -> 0.01347278
B24: Depreciation | C24: =IFERROR('Data Sheet'!B26,0) -> 110.53 | D24: =IFERROR('Data Sheet'!C26,0) -> 131.43 | E24: =IFERROR('Data Sheet'!D26,0) -> 162.84 | F24: =IFERROR('Data Sheet'!E26,0) -> 348 | G24: =IFERROR('Data Sheet'!F26,0) -> 375 | H24: =IFERROR('Data Sheet'!G26,0) -> 399 | I24: =IFERROR('Data Sheet'!H26,0) -> 441 | J24: =IFERROR('Data Sheet'!I26,0) -> 584 | ... L24: =IFERROR('Data Sheet'!K26,0) -> 826 | M24: =IFERROR(SUM('Data Sheet'!H45:K45),0) -> 826
B25: Depreciation % Sales | C25: =C24/C6 -> 0.008335074 | D25: =D24/D6 -> 0.0081533421 | E25: =E24/E6 -> 0.0082331742 | F25: =F24/F6 -> 0.016530496 | G25: =G24/G6 -> 0.017325818 | H25: =H24/H6 -> 0.013854648 | I25: =I24/I6 -> 0.010868762 | J25: =J24/J6 -> 0.011432151 | ... M25: =M24/M6 -> 0.0094309463
B27: Earnings Before Tax | C27: =IFERROR(C18-SUM(C21,C24),0) -> 1015.63 | D27: =IFERROR(D18-SUM(D21,D24),0) -> 1459.85 | E27: =IFERROR(E18-SUM(E21,E24),0) -> 1778.41 | F27: =IFERROR(F18-SUM(F21,F24),0) -> 1949 | G27: =IFERROR(G18-SUM(G21,G24),0) -> 1147 | H27: =IFERROR(H18-SUM(H21,H24),0) -> 2727 | I27: =IFERROR(I18-SUM(I21,I24),0) -> 4141 | J27: =IFERROR(J18-SUM(J21,J24),0) -> 4089 | ... M27: =IFERROR(M18-SUM(M21,M24),0) -> 6350
B28: EBT % Sales | C28: =C27/C6 -> 0.07658872 | D28: =D27/D6 -> 0.090562707 | E28: =E27/E6 -> 0.089916232 | F28: =F27/F6 -> 0.092580277 | G28: =G27/G6 -> 0.052993901 | H28: =H27/H6 -> 0.094690788 | I28: =I27/I6 -> 0.10205792 | J28: =J27/J6 -> 0.080044632 | ... M28: =M27/M6 -> 0.072501827
B30: Tax | C30: =IFERROR('Data Sheet'!B29,0) -> 275.97 | D30: =IFERROR('Data Sheet'!C29,0) -> 427.87 | E30: =IFERROR('Data Sheet'!D29,0) -> 568.24 | F30: =IFERROR('Data Sheet'!E29,0) -> 609 | G30: =IFERROR('Data Sheet'!F29,0) -> 353 | H30: =IFERROR('Data Sheet'!G29,0) -> 706 | I30: =IFERROR('Data Sheet'!H29,0) -> 1173 | J30: =IFERROR('Data Sheet'!I29,0) -> 1127 | ... L30: =IFERROR('Data Sheet'!K29,0) -> 1728 | M30: =IFERROR(SUM('Data Sheet'!H29:K29),0) -> 5226
B31: Effective Tax Rate | C31: =C30/C27 -> 0.27172297 | D31: =D30/D27 -> 0.29309176 | E31: =E30/E27 -> 0.31952137 | F31: =F30/F27 -> 0.31246793 | G31: =G30/G27 -> 0.30775937 | H31: =H30/H27 -> 0.25889256 | I31: =I30/I27 -> 0.28326491 | J31: =J30/J27 -> 0.27561751 | ... M31: =M30/M27 -> 0.82299213
B33: Net Profit | C33: =IFERROR(C27-C30,0) -> 739.66 | D33: =IFERROR(D27-D30,0) -> 1031.98 | E33: =IFERROR(E27-E30,0) -> 1210.17 | F33: =IFERROR(F27-F30,0) -> 1340 | G33: =IFERROR(G27-G30,0) -> 794 | H33: =IFERROR(H27-H30,0) -> 2021 | I33: =IFERROR(I27-I30,0) -> 2968 | J33: =IFERROR(J27-J30,0) -> 2962 | ... M33: =IFERROR(M27-M30,0) -> 1124
B34: Net Margin | C34: =C33/C6 -> 0.055777806 | D34: =D33/D6 -> 0.064019524 | E34: =E33/E6 -> 0.061186075 | F34: =F33/F6 -> 0.06365191 | G34: =G33/G6 -> 0.036684532 | H34: =H33/H6 -> 0.070176048 | I34: =I33/I6 -> 0.07314849 | J34: =J33/J6 -> 0.05798293 | ... M34: =M33/M6 -> 0.012833394
B36: No. Of Equity shares | C36: =IFERROR('Data Sheet'!B93,0) -> 88.78 | D36: =IFERROR('Data Sheet'!C93,0) -> 88.78 | E36: =IFERROR('Data Sheet'!D93,0) -> 88.78 | F36: =IFERROR('Data Sheet'!E93,0) -> 88.78 | G36: =IFERROR('Data Sheet'!F93,0) -> 88.78 | H36: =IFERROR('Data Sheet'!G93,0) -> 88.78 | I36: =IFERROR('Data Sheet'!H93,0) -> 88.78 | J36: =IFERROR('Data Sheet'!I93,0) -> 88.78 | ... L36: =IFERROR('Data Sheet'!K93,0) -> 88.78 | M36: =IFERROR(L36,0) -> 88.78
B38: Earning Per Share | C38: =IFERROR(C33/C36,0) -> 8.3313809 | D38: =IFERROR(D33/D36,0) -> 11.624014 | E38: =IFERROR(E33/E36,0) -> 13.631111 | F38: =IFERROR(F33/F36,0) -> 15.09349 | G38: =IFERROR(G33/G36,0) -> 8.9434557 | H38: =IFERROR(H33/H36,0) -> 22.764136 | I38: =IFERROR(I33/I36,0) -> 33.430953 | J38: =IFERROR(J33/J36,0) -> 33.36337 | ... M38: =IFERROR(M33/M36,0) -> 12.660509
B39: EPS Growth | D39: =IFERROR(D38/C38-1,0) -> 0.39520861 | E39: =IFERROR(E38/D38-1,0) -> 0.17266807 | F39: =IFERROR(F38/E38-1,0) -> 0.10728245 | G39: =IFERROR(G38/F38-1,0) -> -0.40746269 | H39: =IFERROR(H38/G38-1,0) -> 1.5453401 | I39: =IFERROR(I38/H38-1,0) -> 0.46857991 | J39: =IFERROR(J38/I38-1,0) -> -0.0020215633 | K39: =IFERROR(K38/J38-1,0) -> -0.037812289 | ... M39: =IFERROR(M38/L38-1,0) -> -0.75676261
B41: Dividend Per Share | C41: =IFERROR('Data Sheet'!B31/'Historical FS'!C36,0) -> 2.6000225 | D41: =IFERROR('Data Sheet'!C31/'Historical FS'!D36,0) -> 3.7499437 | E41: =IFERROR('Data Sheet'!D31/'Historical FS'!E36,0) -> 5 | F41: =IFERROR('Data Sheet'!E31/'Historical FS'!F36,0) -> 4.0099121 | G41: =IFERROR('Data Sheet'!F31/'Historical FS'!G36,0) -> 4.0099121 | H41: =IFERROR('Data Sheet'!G31/'Historical FS'!H36,0) -> 7.5185853 | I41: =IFERROR('Data Sheet'!H31/'Historical FS'!I36,0) -> 10.02478 | J41: =IFERROR('Data Sheet'!I31/'Historical FS'!J36,0) -> 11.027258 | ... M41: =IFERROR('Data Sheet'!L31/'Historical FS'!M36,0) -> 0
B42: Divident Payout Ratio | C42: =IFERROR(C41/C38,0) -> 0.31207582 | D42: =IFERROR(D41/D38,0) -> 0.32260315 | E42: =IFERROR(E41/E38,0) -> 0.36680797 | F42: =IFERROR(F41/F38,0) -> 0.26567164 | G42: =IFERROR(G41/G38,0) -> 0.44836272 | H42: =IFERROR(H41/H38,0) -> 0.33028204 | I42: =IFERROR(I41/I38,0) -> 0.29986523 | J42: =IFERROR(J41/J38,0) -> 0.33051992 | ... M42: =IFERROR(M41/M38,0) -> 0
B44: Retained Earning | C44: =IFERROR(IF(C38>C41,1-C42,0),0) -> 0.68792418 | D44: =IFERROR(IF(D38>D41,1-D42,0),0) -> 0.67739685 | E44: =IFERROR(IF(E38>E41,1-E42,0),0) -> 0.63319203 | F44: =IFERROR(IF(F38>F41,1-F42,0),0) -> 0.73432836 | G44: =IFERROR(IF(G38>G41,1-G42,0),0) -> 0.55163728 | H44: =IFERROR(IF(H38>H41,1-H42,0),0) -> 0.66971796 | I44: =IFERROR(IF(I38>I41,1-I42,0),0) -> 0.70013477 | J44: =IFERROR(IF(J38>J41,1-J42,0),0) -> 0.66948008 | ... M44: =IFERROR(IF(M38>M41,1-M42,0),0) -> 1
A46: # | B46: Balance Sheet
B47: Equity Share Capital | C47: =IFERROR('Data Sheet'!B57,0) -> 88.78 | D47: =IFERROR('Data Sheet'!C57,0) -> 88.78 | E47: =IFERROR('Data Sheet'!D57,0) -> 88.78 | F47: =IFERROR('Data Sheet'!E57,0) -> 89 | G47: =IFERROR('Data Sheet'!F57,0) -> 89 | H47: =IFERROR('Data Sheet'!G57,0) -> 89 | I47: =IFERROR('Data Sheet'!H57,0) -> 89 | J47: =IFERROR('Data Sheet'!I57,0) -> 89 | ... L47: =IFERROR('Data Sheet'!K57,0) -> 89
B48: Reserves | C48: =IFERROR('Data Sheet'!B58,0) -> 4143.6 | D48: =IFERROR('Data Sheet'!C58,0) -> 5001.1 | E48: =IFERROR('Data Sheet'!D58,0) -> 5981.37 | F48: =IFERROR('Data Sheet'!E58,0) -> 6580 | G48: =IFERROR('Data Sheet'!F58,0) -> 7408 | H48: =IFERROR('Data Sheet'!G58,0) -> 9214 | I48: =IFERROR('Data Sheet'!H58,0) -> 11762 | J48: =IFERROR('Data Sheet'!I58,0) -> 9304 | ... L48: =IFERROR('Data Sheet'!K58,0) -> 15614
B49: Borrowings | C49: =IFERROR('Data Sheet'!B59,0) -> 1882.43 | D49: =IFERROR('Data Sheet'!C59,0) -> 1691.01 | E49: =IFERROR('Data Sheet'!D59,0) -> 2392.98 | F49: =IFERROR('Data Sheet'!E59,0) -> 3562 | G49: =IFERROR('Data Sheet'!F59,0) -> 5638 | H49: =IFERROR('Data Sheet'!G59,0) -> 7275 | I49: =IFERROR('Data Sheet'!H59,0) -> 9367 | J49: =IFERROR('Data Sheet'!I59,0) -> 15528 | ... L49: =IFERROR('Data Sheet'!K59,0) -> 14551
B50: Other Liabilities | C50: =IFERROR('Data Sheet'!B60,0) -> 2292.76 | D50: =IFERROR('Data Sheet'!C60,0) -> 2740.15 | E50: =IFERROR('Data Sheet'!D60,0) -> 3246.71 | F50: =IFERROR('Data Sheet'!E60,0) -> 3313 | G50: =IFERROR('Data Sheet'!F60,0) -> 3309 | H50: =IFERROR('Data Sheet'!G60,0) -> 4610 | I50: =IFERROR('Data Sheet'!H60,0) -> 5802 | J50: =IFERROR('Data Sheet'!I60,0) -> 6626 | ... L50: =IFERROR('Data Sheet'!K60,0) -> 30307
B51: Total Liabilities | C51: =IFERROR('Data Sheet'!B61,0) -> 8407.57 | D51: =IFERROR('Data Sheet'!C61,0) -> 9521.04 | E51: =IFERROR('Data Sheet'!D61,0) -> 11709.84 | F51: =IFERROR('Data Sheet'!E61,0) -> 13544 | G51: =IFERROR('Data Sheet'!F61,0) -> 16444 | H51: =IFERROR('Data Sheet'!G61,0) -> 21188 | I51: =IFERROR('Data Sheet'!H61,0) -> 27020 | J51: =IFERROR('Data Sheet'!I61,0) -> 31547 | ... L51: =IFERROR('Data Sheet'!K61,0) -> 60561
B53: Fixed Assets Net Block | C53: =IFERROR('Data Sheet'!B62,0) -> 1188.72 | D53: =IFERROR('Data Sheet'!C62,0) -> 1473.81 | E53: =IFERROR('Data Sheet'!D62,0) -> 1566.63 | F53: =IFERROR('Data Sheet'!E62,0) -> 2633 | G53: =IFERROR('Data Sheet'!F62,0) -> 2523 | H53: =IFERROR('Data Sheet'!G62,0) -> 2544 | I53: =IFERROR('Data Sheet'!H62,0) -> 2998 | J53: =IFERROR('Data Sheet'!I62,0) -> 3709 | ... L53: =IFERROR('Data Sheet'!K62,0) -> 6906
B54: Capital Work in Progress | C54: =IFERROR('Data Sheet'!B63,0) -> 152.07 | D54: =IFERROR('Data Sheet'!C63,0) -> 43.37 | E54: =IFERROR('Data Sheet'!D63,0) -> 31.77 | F54: =IFERROR('Data Sheet'!E63,0) -> 18 | G54: =IFERROR('Data Sheet'!F63,0) -> 32 | H54: =IFERROR('Data Sheet'!G63,0) -> 85 | I54: =IFERROR('Data Sheet'!H63,0) -> 144 | J54: =IFERROR('Data Sheet'!I63,0) -> 97 | ... L54: =IFERROR('Data Sheet'!K63,0) -> 135
B55: Investments | C55: =IFERROR('Data Sheet'!B64,0) -> 430.73 | D55: =IFERROR('Data Sheet'!C64,0) -> 35.99 | E55: =IFERROR('Data Sheet'!D64,0) -> 108.42 | F55: =IFERROR('Data Sheet'!E64,0) -> 158 | G55: =IFERROR('Data Sheet'!F64,0) -> 2824 | H55: =IFERROR('Data Sheet'!G64,0) -> 294 | I55: =IFERROR('Data Sheet'!H64,0) -> 2515 | J55: =IFERROR('Data Sheet'!I64,0) -> 2345 | ... L55: =IFERROR('Data Sheet'!K64,0) -> 3506
B56: Other Assets | C56: =IFERROR('Data Sheet'!B65-SUM('Data Sheet'!B67:B69),0) -> 723.78 | D56: =IFERROR('Data Sheet'!C65-SUM('Data Sheet'!C67:C69),0) -> 1129.43 | E56: =IFERROR('Data Sheet'!D65-SUM('Data Sheet'!D67:D69),0) -> 1477.27 | F56: =IFERROR('Data Sheet'!E65-SUM('Data Sheet'!E67:E69),0) -> 1939 | G56: =IFERROR('Data Sheet'!F65-SUM('Data Sheet'!F67:F69),0) -> 1731 | H56: =IFERROR('Data Sheet'!G65-SUM('Data Sheet'!G67:G69),0) -> 2518 | I56: =IFERROR('Data Sheet'!H65-SUM('Data Sheet'!H67:H69),0) -> 2762 | J56: =IFERROR('Data Sheet'!I65-SUM('Data Sheet'!I67:I69),0) -> 3801 | ... L56: =IFERROR('Data Sheet'!K65-SUM('Data Sheet'!K67:K69),0) -> 4438
B57: Total Non Current Assets | C57: =SUM(C53:C56) -> 2495.3 | D57: =SUM(D53:D56) -> 2682.6 | E57: =SUM(E53:E56) -> 3184.09 | F57: =SUM(F53:F56) -> 4748 | G57: =SUM(G53:G56) -> 7110 | H57: =SUM(H53:H56) -> 5441 | I57: =SUM(I53:I56) -> 8419 | J57: =SUM(J53:J56) -> 9952 | ... L57: =SUM(L53:L56) -> 14985
...

Sheet Ratio Analysis
B2: ="Ratio Analysis- "&'Data Sheet'!B1 -> Ratio Analysis- TITAN COMPANY LTD
B3: Years | C3: ='Data Sheet'!B16 -> 42825 | D3: ='Data Sheet'!C16 -> 43190 | E3: ='Data Sheet'!D16 -> 43555 | F3: ='Data Sheet'!E16 -> 43921 | G3: ='Data Sheet'!F16 -> 44286 | H3: ='Data Sheet'!G16 -> 44651 | I3: ='Data Sheet'!H16 -> 45016 | J3: ='Data Sheet'!I16 -> 45382 | ... L3: ='Data Sheet'!K16 -> 46112 | M3: Trend | N3: Mean | O3: Median
B5: Sales Growth | D5: ='Historical FS'!D7 -> 0.21559284 | E5: ='Historical FS'!E7 -> 0.22697284 | F5: ='Historical FS'!F7 -> 0.064387022 | G5: ='Historical FS'!G7 -> 0.028120844 | H5: ='Historical FS'!H7 -> 0.3305766 | I5: ='Historical FS'!I7 -> 0.40890309 | J5: ='Historical FS'!J7 -> 0.25900185 | K5: ='Historical FS'!K7 -> 0.18346253 | L5: ='Historical FS'!L7 -> 0.44872304 | N5: =IFERROR(AVERAGE(D5:L5),0) -> 0.24063785 | O5: =IFERROR(MEDIAN(C5:L5),0) -> 0.22697284
B6: EBITDA Growth | D6: =IFERROR('Historical FS'!D18/'Historical FS'!C18-1,0) -> 0.41266432 | E6: =IFERROR('Historical FS'!E18/'Historical FS'!D18-1,0) -> 0.21262012 | F6: =IFERROR('Historical FS'!F18/'Historical FS'!E18-1,0) -> 0.23533572 | G6: =IFERROR('Historical FS'!G18/'Historical FS'!F18-1,0) -> -0.29963459 | H6: =IFERROR('Historical FS'!H18/'Historical FS'!G18-1,0) -> 0.93855072 | I6: =IFERROR('Historical FS'!I18/'Historical FS'!H18-1,0) -> 0.45992823 | J6: =IFERROR('Historical FS'!J18/'Historical FS'!I18-1,0) -> 0.083981975 | K6: =IFERROR('Historical FS'!K18/'Historical FS'!J18-1,0) -> 0.075963719 | L6: =IFERROR('Historical FS'!L18/'Historical FS'!K18-1,0) -> 0.46733404 | N6: =IFERROR(AVERAGE(D6:L6),0) -> 0.28741603 | O6: =IFERROR(MEDIAN(C6:L6),0) -> 0.23533572
B7: EBIT Growth | D7: =IFERROR('Historical FS'!D27/'Historical FS'!C27-1,0) -> 0.43738369 | E7: =IFERROR('Historical FS'!E27/'Historical FS'!D27-1,0) -> 0.2182142 | F7: =IFERROR('Historical FS'!F27/'Historical FS'!E27-1,0) -> 0.095922762 | G7: =IFERROR('Historical FS'!G27/'Historical FS'!F27-1,0) -> -0.41149307 | H7: =IFERROR('Historical FS'!H27/'Historical FS'!G27-1,0) -> 1.3775065 | I7: =IFERROR('Historical FS'!I27/'Historical FS'!H27-1,0) -> 0.51851852 | J7: =IFERROR('Historical FS'!J27/'Historical FS'!I27-1,0) -> -0.012557353 | K7: =IFERROR('Historical FS'!K27/'Historical FS'!J27-1,0) -> -0.010026901 | L7: =IFERROR('Historical FS'!L27/'Historical FS'!K27-1,0) -> 0.56842885 | N7: =IFERROR(AVERAGE(D7:L7),0) -> 0.30909969 | O7: =IFERROR(MEDIAN(C7:L7),0) -> 0.2182142
B8: Net Profit Growth | D8: =IFERROR('Historical FS'!D33/'Historical FS'!C33-1,0) -> 0.39520861 | E8: =IFERROR('Historical FS'!E33/'Historical FS'!D33-1,0) -> 0.17266807 | F8: =IFERROR('Historical FS'!F33/'Historical FS'!E33-1,0) -> 0.10728245 | G8: =IFERROR('Historical FS'!G33/'Historical FS'!F33-1,0) -> -0.40746269 | H8: =IFERROR('Historical FS'!H33/'Historical FS'!G33-1,0) -> 1.5453401 | I8: =IFERROR('Historical FS'!I33/'Historical FS'!H33-1,0) -> 0.46857991 | J8: =IFERROR('Historical FS'!J33/'Historical FS'!I33-1,0) -> -0.0020215633 | K8: =IFERROR('Historical FS'!K33/'Historical FS'!J33-1,0) -> -0.037812289 | L8: =IFERROR('Historical FS'!L33/'Historical FS'!K33-1,0) -> 0.62140351 | N8: =IFERROR(AVERAGE(D8:L8),0) -> 0.31813178 | O8: =IFERROR(MEDIAN(C8:L8),0) -> 0.17266807
B9: Dividend Growth | D9: =IFERROR('Historical FS'!D41/'Historical FS'!C41-1,0) -> 0.44227353 | E9: =IFERROR('Historical FS'!E41/'Historical FS'!D41-1,0) -> 0.33335336 | F9: =IFERROR('Historical FS'!F41/'Historical FS'!E41-1,0) -> -0.19801757 | G9: =IFERROR('Historical FS'!G41/'Historical FS'!F41-1,0) -> 0 | H9: =IFERROR('Historical FS'!H41/'Historical FS'!G41-1,0) -> 0.875 | I9: =IFERROR('Historical FS'!I41/'Historical FS'!H41-1,0) -> 0.33333333 | J9: =IFERROR('Historical FS'!J41/'Historical FS'!I41-1,0) -> 0.1 | K9: =IFERROR('Historical FS'!K41/'Historical FS'!J41-1,0) -> 0 | L9: =IFERROR('Historical FS'!L41/'Historical FS'!K41-1,0) -> 0.36363636 | N9: =IFERROR(AVERAGE(D9:L9),0) -> 0.24995322 | O9: =IFERROR(MEDIAN(C9:L9),0) -> 0.33333333
B11: Gross Margin | C11: =IFERROR('Historical FS'!C13,0) -> 0.20020014 | D11: =IFERROR('Historical FS'!D13,0) -> 0.20826228 | E11: =IFERROR('Historical FS'!E13,0) -> 0.20820769 | F11: =IFERROR('Historical FS'!F13,0) -> 0.21024131 | G11: =IFERROR('Historical FS'!G13,0) -> 0.18402329 | H11: =IFERROR('Historical FS'!H13,0) -> 0.19354839 | I11: =IFERROR('Historical FS'!I13,0) -> 0.20406654 | J11: =IFERROR('Historical FS'!J13,0) -> 0.18440216 | ... L11: =IFERROR('Historical FS'!L13,0) -> 0.16665144 | N11: =IFERROR(AVERAGE(C11:L11),0) -> 0.19321585 | O11: =IFERROR(MEDIAN(C11:L11),0) -> 0.19687426
B12: EBITDA Margin | C12: =IFERROR('Historical FS'!C19,0) -> 0.08776977 | D12: =IFERROR('Historical FS'!D19,0) -> 0.10199897 | E12: =IFERROR('Historical FS'!E19,0) -> 0.10080582 | F12: =IFERROR('Historical FS'!F19,0) -> 0.11699601 | G12: =IFERROR('Historical FS'!G19,0) -> 0.079698762 | H12: =IFERROR('Historical FS'!H19,0) -> 0.11611514 | I12: =IFERROR('Historical FS'!I19,0) -> 0.12032039 | J12: =IFERROR('Historical FS'!J19,0) -> 0.10359408 | ... L12: =IFERROR('Historical FS'!L19,0) -> 0.095394136 | N12: =IFERROR(AVERAGE(C12:L12),0) -> 0.10168773 | O12: =IFERROR(MEDIAN(C12:L12),0) -> 0.1014024
B13: EBIT/ Operating Margin | C13: =IFERROR(('Historical FS'!C18-'Historical FS'!C24)/'Historical FS'!C6,0) -> 0.079434696 | D13: =IFERROR(('Historical FS'!D18-'Historical FS'!D24)/'Historical FS'!D6,0) -> 0.093845632 | E13: =IFERROR(('Historical FS'!E18-'Historical FS'!E24)/'Historical FS'!E6,0) -> 0.09257265 | F13: =IFERROR(('Historical FS'!F18-'Historical FS'!F24)/'Historical FS'!F6,0) -> 0.10046551 | G13: =IFERROR(('Historical FS'!G18-'Historical FS'!G24)/'Historical FS'!G6,0) -> 0.062372944 | H13: =IFERROR(('Historical FS'!H18-'Historical FS'!H24)/'Historical FS'!H6,0) -> 0.1022605 | I13: =IFERROR(('Historical FS'!I18-'Historical FS'!I24)/'Historical FS'!I6,0) -> 0.10945163 | J13: =IFERROR(('Historical FS'!J18-'Historical FS'!J24)/'Historical FS'!J6,0) -> 0.092161929 | ... L13: =IFERROR(('Historical FS'!L18-'Historical FS'!L24)/'Historical FS'!L6,0) -> 0.08596319 | N13: =IFERROR(AVERAGE(C13:L13),0) -> 0.090125 | O13: =IFERROR(MEDIAN(C13:L13),0) -> 0.092367289
B14: EBT Margin | C14: =IFERROR('Historical FS'!C28,0) -> 0.07658872 | D14: =IFERROR('Historical FS'!D28,0) -> 0.090562707 | E14: =IFERROR('Historical FS'!E28,0) -> 0.089916232 | F14: =IFERROR('Historical FS'!F28,0) -> 0.092580277 | G14: =IFERROR('Historical FS'!G28,0) -> 0.052993901 | H14: =IFERROR('Historical FS'!H28,0) -> 0.094690788 | I14: =IFERROR('Historical FS'!I28,0) -> 0.10205792 | J14: =IFERROR('Historical FS'!J28,0) -> 0.080044632 | ... L14: =IFERROR('Historical FS'!L28,0) -> 0.072490409 | N14: =IFERROR(AVERAGE(C14:L14),0) -> 0.081888337 | O14: =IFERROR(MEDIAN(C14:L14),0) -> 0.084980432
B15: Net Profit Margin | C15: =IFERROR('Historical FS'!C34,0) -> 0.055777806 | D15: =IFERROR('Historical FS'!D34,0) -> 0.064019524 | E15: =IFERROR('Historical FS'!E34,0) -> 0.061186075 | F15: =IFERROR('Historical FS'!F34,0) -> 0.06365191 | G15: =IFERROR('Historical FS'!G34,0) -> 0.036684532 | H15: =IFERROR('Historical FS'!H34,0) -> 0.070176048 | I15: =IFERROR('Historical FS'!I34,0) -> 0.07314849 | J15: =IFERROR('Historical FS'!J34,0) -> 0.05798293 | ... L15: =IFERROR('Historical FS'!L34,0) -> 0.052760778 | N15: =IFERROR(AVERAGE(C15:L15),0) -> 0.058252981 | O15: =IFERROR(MEDIAN(C15:L15),0) -> 0.059584502
B17: SalesExpenses%Sales | C17: =IFERROR('Historical FS'!C16,0) -> 0.11243037 | D17: =IFERROR('Historical FS'!D16,0) -> 0.1062633 | E17: =IFERROR('Historical FS'!E16,0) -> 0.10740187 | F17: =IFERROR('Historical FS'!F16,0) -> 0.093245297 | G17: =IFERROR('Historical FS'!G16,0) -> 0.10432452 | H17: =IFERROR('Historical FS'!H16,0) -> 0.077433244 | I17: =IFERROR('Historical FS'!I16,0) -> 0.083746149 | J17: =IFERROR('Historical FS'!J16,0) -> 0.080808081 | ... L17: =IFERROR('Historical FS'!L16,0) -> 0.071257307 | N17: =IFERROR(AVERAGE(C17:L17),0) -> 0.091528119 | O17: =IFERROR(MEDIAN(C17:L17),0) -> 0.088495723
B18: Depreciation%Sales | C18: =IFERROR('Historical FS'!C25,0) -> 0.008335074 | D18: =IFERROR('Historical FS'!D25,0) -> 0.0081533421 | E18: =IFERROR('Historical FS'!E25,0) -> 0.0082331742 | F18: =IFERROR('Historical FS'!F25,0) -> 0.016530496 | G18: =IFERROR('Historical FS'!G25,0) -> 0.017325818 | H18: =IFERROR('Historical FS'!H25,0) -> 0.013854648 | I18: =IFERROR('Historical FS'!I25,0) -> 0.010868762 | J18: =IFERROR('Historical FS'!J25,0) -> 0.011432151 | ... L18: =IFERROR('Historical FS'!L25,0) -> 0.0094309463 | N18: =IFERROR(AVERAGE(C18:L18),0) -> 0.011562729 | O18: =IFERROR(MEDIAN(C18:L18),0) -> 0.011150456
B19: OperatingIncome%Sales | C19: =C13 -> 0.079434696 | D19: =D13 -> 0.093845632 | E19: =E13 -> 0.09257265 | F19: =F13 -> 0.10046551 | G19: =G13 -> 0.062372944 | H19: =H13 -> 0.1022605 | I19: =I13 -> 0.10945163 | J19: =J13 -> 0.092161929 | ... L19: =L13 -> 0.08596319 | N19: =IFERROR(AVERAGE(C19:L19),0) -> 0.090125 | O19: =IFERROR(MEDIAN(C19:L19),0) -> 0.092367289
B21: Return on Capital Employed | C21: =IFERROR(('Historical FS'!C18-'Historical FS'!C24)/(SUM('Historical FS'!C47:C49)),0) -> 0.17226537 | D21: =IFERROR(('Historical FS'!D18-'Historical FS'!D24)/(SUM('Historical FS'!D47:D49)),0) -> 0.22309313 | E21: =IFERROR(('Historical FS'!E18-'Historical FS'!E24)/(SUM('Historical FS'!E47:E49)),0) -> 0.21634431 | F21: =IFERROR(('Historical FS'!F18-'Historical FS'!F24)/(SUM('Historical FS'!F47:F49)),0) -> 0.20672466 | G21: =IFERROR(('Historical FS'!G18-'Historical FS'!G24)/(SUM('Historical FS'!G47:G49)),0) -> 0.10277884 | H21: =IFERROR(('Historical FS'!H18-'Historical FS'!H24)/(SUM('Historical FS'!H47:H49)),0) -> 0.17764507 | I21: =IFERROR(('Historical FS'!I18-'Historical FS'!I24)/(SUM('Historical FS'!I47:I49)),0) -> 0.20930342 | J21: =IFERROR(('Historical FS'!J18-'Historical FS'!J24)/(SUM('Historical FS'!J47:J49)),0) -> 0.18891698 | ... L21: =IFERROR(('Historical FS'!L18-'Historical FS'!L24)/(SUM('Historical FS'!L47:L49)),0) -> 0.24885965 | N21: =IFERROR(AVERAGE(C21:L21),0) -> 0.19002785 | O21: =IFERROR(MEDIAN(C21:L21),0) -> 0.19782082
B22: Retained Earning% | C22: ='Historical FS'!C44 -> 0.68792418 | D22: ='Historical FS'!D44 -> 0.67739685 | E22: ='Historical FS'!E44 -> 0.63319203 | F22: ='Historical FS'!F44 -> 0.73432836 | G22: ='Historical FS'!G44 -> 0.55163728 | H22: ='Historical FS'!H44 -> 0.66971796 | I22: ='Historical FS'!I44 -> 0.70013477 | J22: ='Historical FS'!J44 -> 0.66948008 | ... L22: ='Historical FS'!L44 -> 0.71110149 | N22: =IFERROR(AVERAGE(C22:L22),0) -> 0.66914042 | O22: =IFERROR(MEDIAN(C22:L22),0) -> 0.67355741
B23: Return on Equity% | C23: =IFERROR('Historical FS'!C33/SUM('Historical FS'!C47:C48),0) -> 0.17476219 | D23: =IFERROR('Historical FS'!D33/SUM('Historical FS'!D47:D48),0) -> 0.20275134 | E23: =IFERROR('Historical FS'!E33/SUM('Historical FS'!E47:E48),0) -> 0.1993641 | F23: =IFERROR('Historical FS'!F33/SUM('Historical FS'!F47:F48),0) -> 0.20092967 | G23: =IFERROR('Historical FS'!G33/SUM('Historical FS'!G47:G48),0) -> 0.10590903 | H23: =IFERROR('Historical FS'!H33/SUM('Historical FS'!H47:H48),0) -> 0.21724175 | I23: =IFERROR('Historical FS'!I33/SUM('Historical FS'!I47:I48),0) -> 0.250443 | J23: =IFERROR('Historical FS'!J33/SUM('Historical FS'!J47:J48),0) -> 0.31534121 | ... L23: =IFERROR('Historical FS'!L33/SUM('Historical FS'!L47:L48),0) -> 0.29427498 | N23: =IFERROR(AVERAGE(C23:L23),0) -> 0.22061997 | O23: =IFERROR(MEDIAN(C23:L23),0) -> 0.20999655
B24: Self Sustainable Growth Rate | C24: =IFERROR(C22*C23,0) -> 0.12022314 | D24: =IFERROR(D22*D23,0) -> 0.13734312 | E24: =IFERROR(E22*E23,0) -> 0.12623576 | F24: =IFERROR(F22*F23,0) -> 0.14754836 | G24: =IFERROR(G22*G23,0) -> 0.058423369 | H24: =IFERROR(H22*H23,0) -> 0.1454907 | I24: =IFERROR(I22*I23,0) -> 0.17534385 | J24: =IFERROR(J22*J23,0) -> 0.21111466 | ... L24: =IFERROR(L22*L23,0) -> 0.20925938 | N24: =IFERROR(AVERAGE(C24:L24),0) -> 0.14919424 | O24: =IFERROR(MEDIAN(C24:L24),0) -> 0.14651953
B25: Interest Coverage Ratio | C25: =IFERROR(('Historical FS'!C18-'Historical FS'!C24)/('Historical FS'!C21),0) -> 27.911235 | D25: =IFERROR(('Historical FS'!D18-'Historical FS'!D24)/('Historical FS'!D21),0) -> 28.585979 | E25: =IFERROR(('Historical FS'!E18-'Historical FS'!E24)/('Historical FS'!E21),0) -> 34.848687 | F25: =IFERROR(('Historical FS'!F18-'Historical FS'!F24)/('Historical FS'!F21),0) -> 12.740964 | G25: =IFERROR(('Historical FS'!G18-'Historical FS'!G24)/('Historical FS'!G21),0) -> 6.6502463 | H25: =IFERROR(('Historical FS'!H18-'Historical FS'!H24)/('Historical FS'!H21),0) -> 13.509174 | I25: =IFERROR(('Historical FS'!I18-'Historical FS'!I24)/('Historical FS'!I21),0) -> 14.803333 | J25: =IFERROR(('Historical FS'!J18-'Historical FS'!J24)/('Historical FS'!J21),0) -> 7.6058158 | ... L25: =IFERROR(('Historical FS'!L18-'Historical FS'!L24)/('Historical FS'!L21),0) -> 6.3805085 | N25: =IFERROR(AVERAGE(C25:L25),0) -> 15.828358 | O25: =IFERROR(MEDIAN(C25:L25),0) -> 13.125069
B27: Debtor Turnover Ratio | C27: =IFERROR('Historical FS'!C6/'Historical FS'!C59,0) -> 63.87683 | D27: =IFERROR('Historical FS'!D6/'Historical FS'!D59,0) -> 54.515777 | E27: =IFERROR('Historical FS'!E6/'Historical FS'!E59,0) -> 47.041313 | F27: =IFERROR('Historical FS'!F6/'Historical FS'!F59,0) -> 67.474359 | G27: =IFERROR('Historical FS'!G6/'Historical FS'!G59,0) -> 59.136612 | H27: =IFERROR('Historical FS'!H6/'Historical FS'!H59,0) -> 50.971681 | I27: =IFERROR('Historical FS'!I6/'Historical FS'!I59,0) -> 60.200297 | J27: =IFERROR('Historical FS'!J6/'Historical FS'!J59,0) -> 50.180747 | ... L27: =IFERROR('Historical FS'!L6/'Historical FS'!L59,0) -> 95.615721 | N27: =IFERROR(AVERAGE(C27:L27),0) -> 60.562008 | O27: =IFERROR(MEDIAN(C27:L27),0) -> 57.871677
B28: Creditor Turnover Ratio | C28: =IFERROR('Historical FS'!C6/'Historical FS'!C50,0) -> 5.7837846 | D28: =IFERROR('Historical FS'!D6/'Historical FS'!D50,0) -> 5.8828057 | E28: =IFERROR('Historical FS'!E6/'Historical FS'!E50,0) -> 6.0918653 | F28: =IFERROR('Historical FS'!F6/'Historical FS'!F50,0) -> 6.3543616 | G28: =IFERROR('Historical FS'!G6/'Historical FS'!G50,0) -> 6.5409489 | H28: =IFERROR('Historical FS'!H6/'Historical FS'!H50,0) -> 6.2470716 | I28: =IFERROR('Historical FS'!I6/'Historical FS'!I50,0) -> 6.9932782 | J28: =IFERROR('Historical FS'!J6/'Historical FS'!J50,0) -> 7.7096287 | ... L28: =IFERROR('Historical FS'!L6/'Historical FS'!L50,0) -> 2.8898934 | N28: =IFERROR(AVERAGE(C28:L28),0) -> 6.1826971 | O28: =IFERROR(MEDIAN(C28:L28),0) -> 6.3007166
B29: Inverntory Turnover | C29: =IFERROR('Historical FS'!C6/'Historical FS'!C60,0) -> 2.6921498 | D29: =IFERROR('Historical FS'!D6/'Historical FS'!D60,0) -> 2.7207098 | E29: =IFERROR('Historical FS'!E6/'Historical FS'!E60,0) -> 2.8099198 | F29: =IFERROR('Historical FS'!F6/'Historical FS'!F60,0) -> 2.5980501 | G29: =IFERROR('Historical FS'!G6/'Historical FS'!G60,0) -> 2.574215 | H29: =IFERROR('Historical FS'!H6/'Historical FS'!H60,0) -> 2.1161731 | I29: =IFERROR('Historical FS'!I6/'Historical FS'!I60,0) -> 2.4466353 | J29: =IFERROR('Historical FS'!J6/'Historical FS'!J60,0) -> 2.681434 | ... L29: =IFERROR('Historical FS'!L6/'Historical FS'!L60,0) -> 2.0490841 | N29: =IFERROR(AVERAGE(C29:L29),0) -> 2.4833418 | O29: =IFERROR(MEDIAN(C29:L29),0) -> 2.5861326
B30: Fixed Asset Turnover | C30: =IFERROR('Historical FS'!C6/'Historical FS'!C53,0) -> 11.155554 | D30: =IFERROR('Historical FS'!D6/'Historical FS'!D53,0) -> 10.937482 | E30: =IFERROR('Historical FS'!E6/'Historical FS'!E53,0) -> 12.624883 | F30: =IFERROR('Historical FS'!F6/'Historical FS'!F53,0) -> 7.9954425 | G30: =IFERROR('Historical FS'!G6/'Historical FS'!G53,0) -> 8.5786762 | H30: =IFERROR('Historical FS'!H6/'Historical FS'!H53,0) -> 11.320362 | I30: =IFERROR('Historical FS'!I6/'Historical FS'!I53,0) -> 13.534023 | J30: =IFERROR('Historical FS'!J6/'Historical FS'!J53,0) -> 13.772985 | ... L30: =IFERROR('Historical FS'!L6/'Historical FS'!L53,0) -> 12.682305 | N30: =IFERROR(AVERAGE(C30:L30),0) -> 11.748502 | O30: =IFERROR(MEDIAN(C30:L30),0) -> 11.972622
B31: Capital Turnover Ratio | C31: =IFERROR('Historical FS'!C6/SUM('Historical FS'!C47:C48),0) -> 3.1331851 | D31: =IFERROR('Historical FS'!D6/SUM('Historical FS'!D47:D48),0) -> 3.1670236 | E31: =IFERROR('Historical FS'!E6/SUM('Historical FS'!E47:E48),0) -> 3.2583248 | F31: =IFERROR('Historical FS'!F6/SUM('Historical FS'!F47:F48),0) -> 3.1566952 | G31: =IFERROR('Historical FS'!G6/SUM('Historical FS'!G47:G48),0) -> 2.8870215 | H31: =IFERROR('Historical FS'!H6/SUM('Historical FS'!H47:H48),0) -> 3.0956681 | I31: =IFERROR('Historical FS'!I6/SUM('Historical FS'!I47:I48),0) -> 3.4237617 | J31: =IFERROR('Historical FS'!J6/SUM('Historical FS'!J47:J48),0) -> 5.438518 | ... L31: =IFERROR('Historical FS'!L6/SUM('Historical FS'!L47:L48),0) -> 5.577533 | N31: =IFERROR(AVERAGE(C31:L31),0) -> 3.8338694 | O31: =IFERROR(MEDIAN(C31:L31),0) -> 3.2126742
B33: Debtor Days | C33: =IFERROR(365/C27,0) -> 5.714122 | D33: =IFERROR(365/D27,0) -> 6.6953095 | E33: =IFERROR(365/E27,0) -> 7.7591372 | F33: =IFERROR(365/F27,0) -> 5.4094623 | G33: =IFERROR(365/G27,0) -> 6.1721493 | H33: =IFERROR(365/H27,0) -> 7.1608389 | I33: =IFERROR(365/I27,0) -> 6.063093 | J33: =IFERROR(365/J27,0) -> 7.2737061 | ... L33: =IFERROR(365/L27,0) -> 3.8173639 | N33: =IFERROR(AVERAGE(C33:L33),0) -> 6.2513177 | O33: =IFERROR(MEDIAN(C33:L33),0) -> 6.3100723
B34: Payable Days | C34: =IFERROR(365/C28,0) -> 63.107468 | D34: =IFERROR(365/D28,0) -> 62.045225 | E34: =IFERROR(365/E28,0) -> 59.915967 | F34: =IFERROR(365/F28,0) -> 57.440861 | G34: =IFERROR(365/G28,0) -> 55.802301 | H34: =IFERROR(365/H28,0) -> 58.427376 | I34: =IFERROR(365/I28,0) -> 52.192976 | J34: =IFERROR(365/J28,0) -> 47.343395 | ... L34: =IFERROR(365/L28,0) -> 126.30224 | N34: =IFERROR(AVERAGE(C34:L34),0) -> 63.235053 | O34: =IFERROR(MEDIAN(C34:L34),0) -> 57.934118
B35: Inventory Days | C35: =IFERROR(365/C29,0) -> 135.57938 | D35: =IFERROR(365/D29,0) -> 134.15617 | E35: =IFERROR(365/E29,0) -> 129.89694 | F35: =IFERROR(365/F29,0) -> 140.48998 | G35: =IFERROR(365/G29,0) -> 141.7908 | H35: =IFERROR(365/H29,0) -> 172.48116 | I35: =IFERROR(365/I29,0) -> 149.18447 | J35: =IFERROR(365/J29,0) -> 136.12119 | ... L35: =IFERROR(365/L29,0) -> 178.12837 | N35: =IFERROR(AVERAGE(C35:L35),0) -> 148.79879 | O35: =IFERROR(MEDIAN(C35:L35),0) -> 141.14039
B36: Cash Conversion Cash (in days) | C36: =IFERROR(SUM(C33,C35)-C34,0) -> 78.186034 | D36: =IFERROR(SUM(D33,D35)-D34,0) -> 78.806255 | E36: =IFERROR(SUM(E33,E35)-E34,0) -> 77.740114 | F36: =IFERROR(SUM(F33,F35)-F34,0) -> 88.458579 | G36: =IFERROR(SUM(G33,G35)-G34,0) -> 92.160645 | H36: =IFERROR(SUM(H33,H35)-H34,0) -> 121.21463 | I36: =IFERROR(SUM(I33,I35)-I34,0) -> 103.05459 | J36: =IFERROR(SUM(J33,J35)-J34,0) -> 96.051503 | ... L36: =IFERROR(SUM(L33,L35)-L34,0) -> 55.643497 | N36: =IFERROR(AVERAGE(C36:L36),0) -> 91.815056 | O36: =IFERROR(MEDIAN(C36:L36),0) -> 90.309612
B38: CFO/Sales | C38: =IFERROR('Historical FS'!C79/'Historical FS'!C6,0) -> 0.34816825 | D38: =IFERROR('Historical FS'!D79/'Historical FS'!D6,0) -> -0.054715421 | E38: =IFERROR('Historical FS'!E79/'Historical FS'!E6,0) -> 0.1424778 | F38: =IFERROR('Historical FS'!F79/'Historical FS'!F6,0) -> -0.11452594 | G38: =IFERROR('Historical FS'!G79/'Historical FS'!G6,0) -> 0.51607836 | H38: =IFERROR('Historical FS'!H79/'Historical FS'!H6,0) -> -0.13424077 | I38: =IFERROR('Historical FS'!I79/'Historical FS'!I6,0) -> 0.036500308 | J38: =IFERROR('Historical FS'!J79/'Historical FS'!J6,0) -> 0.039679743 | ... L38: =IFERROR('Historical FS'!L79/'Historical FS'!L6,0) -> 0.13469355 | N38: =IFERROR(AVERAGE(C38:L38),0) -> 0.082778864
B39: CFO/Total Assets | C39: =IFERROR('Historical FS'!C79/'Historical FS'!C64,0) -> 0.54914797 | D39: =IFERROR('Historical FS'!D79/'Historical FS'!D64,0) -> -0.092636939 | E39: =IFERROR('Historical FS'!E79/'Historical FS'!E64,0) -> 0.24065231 | F39: =IFERROR('Historical FS'!F79/'Historical FS'!F64,0) -> -0.1780124 | G39: =IFERROR('Historical FS'!G79/'Historical FS'!G64,0) -> 0.67927512 | H39: =IFERROR('Historical FS'!H79/'Historical FS'!H64,0) -> -0.18246177 | I39: =IFERROR('Historical FS'!I79/'Historical FS'!I64,0) -> 0.054811251 | J39: =IFERROR('Historical FS'!J79/'Historical FS'!J64,0) -> 0.064253336 | ... L39: =IFERROR('Historical FS'!L79/'Historical FS'!L64,0) -> 0.19479533 | N39: =IFERROR(AVERAGE(C39:L39),0) -> 0.12014197
B40: CFO/Total Debt | C40: =IFERROR('Historical FS'!C79/'Historical FS'!C49,0) -> 2.4526808 | D40: =IFERROR('Historical FS'!D79/'Historical FS'!D49,0) -> -0.52158178 | E40: =IFERROR('Historical FS'!E79/'Historical FS'!E49,0) -> 1.1776112 | F40: =IFERROR('Historical FS'!F79/'Historical FS'!F49,0) -> -0.67686693 | G40: =IFERROR('Historical FS'!G79/'Historical FS'!G49,0) -> 1.981199 | H40: =IFERROR('Historical FS'!H79/'Historical FS'!H49,0) -> -0.53140893 | I40: =IFERROR('Historical FS'!I79/'Historical FS'!I49,0) -> 0.15810825 | J40: =IFERROR('Historical FS'!J79/'Historical FS'!J49,0) -> 0.13053838 | ... L40: =IFERROR('Historical FS'!L79/'Historical FS'!L49,0) -> 0.81073466 | N40: =IFERROR(AVERAGE(C40:L40),0) -> 0.47298235

Sheet Forecasting
B2: ='Data Sheet'!B1&" - "&'Data Sheet'!A17&" Forecasting " -> TITAN COMPANY LTD - Sales Forecasting | G2: ='Data Sheet'!B1&" - "&'Historical FS'!B18&" Forecasting " -> TITAN COMPANY LTD - EBITDA Forecasting | L2: ='Data Sheet'!B1&" - "&'Historical FS'!B38&" Forecasting " -> TITAN COMPANY LTD - Earning Per Share Forecasting
B3: Year weight | C3: Year | D3: Sales | E3: Sales growth | G3: Year weight | H3: Year | I3: EBITDA | J3: EBITDA Growth | L3: Year weight | M3: Year | N3: EPS | O3: EPS Growth
